Workbook

Sheet Assumptions
A1: Tesla Valuation Model — Base Case Assumptions
A2: Valuation Target Year | B2: 2028 | C2: Forward-looking model — not based on current reported figures
A4: FLEET & FSD
A5: Fleet Size (millions) | B5: 9 | C5: Cumulative deliveries through 2028E
A6: FSD Penetration | B6: 0.3 | C6: % of fleet on paid FSD subscription
A7: FSD Price per year ($) | B7: 1200 | C7: $99/month × 12 — Tesla current rate (tesla.com)
A8: FSD Margin | B8: 0.75 | C8: Software gross margin estimate
A9: FSD Revenue Multiple | B9: 25 | C9: P/E applied to FSD profit
A11: EV SEGMENT
A12: EV Earnings ($B) | B12: 13 | C12: Forward 2028E target (vs. $3.8B actual 2025)
A13: EV Multiple | B13: 20 | C13: P/E multiple — conservative for EV leader
A15: ROBOTAXI SEGMENT
A16: Robotaxi Vehicles (millions) | B16: 2 | C16: Speculative 2028E fleet target
A17: Revenue per Robotaxi ($) | B17: 25000 | C17: Annual gross revenue per vehicle
A18: Take Rate | B18: 0.25 | C18: Tesla's platform commission
A19: Robotaxi Margin | B19: 0.45 | C19: Operating margin on Tesla's net revenue
A20: Robotaxi Revenue Multiple | B20: 25 | C20: P/E applied to robotaxi profit
A22: CAPITAL STRUCTURE ★ NEW
A23: Shares Outstanding (millions) | B23: 3200 | C23: ~3,200M diluted shares (Q1 2026 10-Q)
A24: Net Cash / (Debt) ($B) | B24: 37 | C24: Cash $36.8B - Debt; Tesla net cash positive
A26: COLOR LEGEND
A27: ■ | B27: Blue text — hardcoded input (change these to sensitise)
A28: ■ | B28: Black text — formula / calculated value
A29: ■ | B29: Green text — cross-sheet reference

Sheet Model
A1: Base Case — Detailed Calculations (all inputs from Assumptions sheet)
A2: FSD SEGMENT
A3: FSD Users (millions) | B3: =Assumptions!B5*Assumptions!B6 -> 2.7
A4: FSD Revenue ($B) | B4: =B3*Assumptions!B7/1000 -> 3.24
A5: FSD Profit ($B) | B5: =B4*Assumptions!B8 -> 2.43
A6: FSD Valuation ($B) | B6: =B5*Assumptions!B9 -> 60.75
A8: EV SEGMENT
A9: EV Valuation ($B) | B9: =Assumptions!B12*Assumptions!B13 -> 260
A11: ROBOTAXI SEGMENT
A12: Gross Revenue ($B) | B12: =Assumptions!B16*Assumptions!B17/1000 -> 50
A13: Tesla Share Revenue ($B) | B13: =B12*Assumptions!B18 -> 12.5
A14: Robotaxi Profit ($B) | B14: =B13*Assumptions!B19 -> 5.625
A15: Robotaxi Valuation ($B) | B15: =B14*Assumptions!B20 -> 140.625
A17: ENTERPRISE VALUE
A18: Total Enterprise Value ($B) | B18: =B6+B9+B15 -> 461.375
A20: EQUITY BRIDGE ★ NEW
A21: Add: Net Cash / (Debt) ($B) | B21: =Assumptions!B24 -> 37
A22: Equity Value ($B) | B22: =B18+B21 -> 498.375
A23: Shares Outstanding (millions) | B23: =Assumptions!B23 -> 3200
A24: Implied Share Price ($) | B24: =B22*1000/B23 -> 155.74219

Sheet Scenarios
A1: Scenario Analysis — Target Year: 2028
B2: Bear | C2: Base | D2: Bull
A3: Probability | B3: 0.2 | C3: 0.5 | D3: 0.3
A4: Valuation Target Year | B4: =Assumptions!B2 -> 2028 | C4: =Assumptions!B2 -> 2028 | D4: =Assumptions!B2 -> 2028
A6: SCENARIO-SPECIFIC ASSUMPTIONS ★ NEW (replacing flat multipliers)
A7: FSD Penetration | B7: 0.15 | C7: 0.3 | D7: 0.5
A8: EV Earnings ($B) | B8: 8 | C8: 13 | D8: 18
A9: FSD Revenue Multiple | B9: 20 | C9: 25 | D9: 30
A10: EV Earnings Multiple | B10: 15 | C10: 20 | D10: 25
A11: Robotaxi Vehicles (millions) | B11: 0.5 | C11: 2 | D11: 4
A12: Robotaxi Revenue Multiple | B12: 20 | C12: 25 | D12: 35
A14: FIXED ASSUMPTIONS (shared across all scenarios — from Assumptions sheet)
A15: Fleet Size (millions) | B15: =Assumptions!B5 -> 9 | C15: =Assumptions!B5 -> 9 | D15: =Assumptions!B5 -> 9
A16: FSD Price per year ($) | B16: =Assumptions!B7 -> 1200 | C16: =Assumptions!B7 -> 1200 | D16: =Assumptions!B7 -> 1200
A17: FSD Margin | B17: =Assumptions!B8 -> 0.75 | C17: =Assumptions!B8 -> 0.75 | D17: =Assumptions!B8 -> 0.75
A18: Revenue per Robotaxi ($) | B18: =Assumptions!B17 -> 25000 | C18: =Assumptions!B17 -> 25000 | D18: =Assumptions!B17 -> 25000
A19: Take Rate | B19: =Assumptions!B18 -> 0.25 | C19: =Assumptions!B18 -> 0.25 | D19: =Assumptions!B18 -> 0.25
A20: Robotaxi Margin | B20: =Assumptions!B19 -> 0.45 | C20: =Assumptions!B19 -> 0.45 | D20: =Assumptions!B19 -> 0.45
A22: FSD SEGMENT
A23: FSD Users (millions) | B23: =B15*B7 -> 1.35 | C23: =C15*C7 -> 2.7 | D23: =D15*D7 -> 4.5
A24: FSD Revenue ($B) | B24: =B23*B16/1000 -> 1.62 | C24: =C23*C16/1000 -> 3.24 | D24: =D23*D16/1000 -> 5.4
A25: FSD Profit ($B) | B25: =B24*B17 -> 1.215 | C25: =C24*C17 -> 2.43 | D25: =D24*D17 -> 4.05
A26: FSD Valuation ($B) | B26: =B25*B9 -> 24.3 | C26: =C25*C9 -> 60.75 | D26: =D25*D9 -> 121.5
A28: EV SEGMENT
A29: EV Valuation ($B) | B29: =B8*B10 -> 120 | C29: =C8*C10 -> 260 | D29: =D8*D10 -> 450
A31: ROBOTAXI SEGMENT
A32: Gross Revenue ($B) | B32: =B11*B18/1000 -> 12.5 | C32: =C11*C18/1000 -> 50 | D32: =D11*D18/1000 -> 100
A33: Tesla Share Revenue ($B) | B33: =B32*B19 -> 3.125 | C33: =C32*C19 -> 12.5 | D33: =D32*D19 -> 25
A34: Robotaxi Profit ($B) | B34: =B33*B20 -> 1.40625 | C34: =C33*C20 -> 5.625 | D34: =D33*D20 -> 11.25
A35: Robotaxi Valuation ($B) | B35: =B34*B12 -> 28.125 | C35: =C34*C12 -> 140.625 | D35: =D34*D12 -> 393.75
A37: ENTERPRISE VALUE
A38: Total Enterprise Value ($B) | B38: =B26+B29+B35 -> 172.425 | C38: =C26+C29+C35 -> 461.375 | D38: =D26+D29+D35 -> 965.25
A40: EQUITY BRIDGE ★ NEW
A41: Add: Net Cash / (Debt) ($B) | B41: =Assumptions!B24 -> 37 | C41: =Assumptions!B24 -> 37 | D41: =Assumptions!B24 -> 37
A42: Equity Value ($B) | B42: =B38+B41 -> 209.425 | C42: =C38+C41 -> 498.375 | D42: =D38+D41 -> 1002.25
A43: Shares Outstanding (millions) | B43: =Assumptions!B23 -> 3200 | C43: =Assumptions!B23 -> 3200 | D43: =Assumptions!B23 -> 3200
A44: Implied Share Price ($) | B44: =B42*1000/B43 -> 65.445312 | C44: =C42*1000/C43 -> 155.74219 | D44: =D42*1000/D43 -> 313.20312
A46: PROBABILITY WEIGHTING
A47: Weighted Enterprise Value ($B) | B47: =B3*B38 -> 34.485 | C47: =C3*C38 -> 230.6875 | D47: =D3*D38 -> 289.575
A48: Weighted Equity Value ($B) | B48: =B3*B42 -> 41.885 | C48: =C3*C42 -> 249.1875 | D48: =D3*D42 -> 300.675
...
